Workbook

Sheet Monthly Housing Constructions 1
D1: Average | E1: Median
A2: 2023 | D2: =AVERAGE(C3:C10) -> 120 | E2: =MEDIAN(C3:C10) -> 117.95
B3: August | C3: 114.2
B4: July | C4: 130.6
B5: June | C5: 132.6
B6: May | C6: 146
B7: April | C7: 121.7
B8: March | C8: 114
B9: Feb | C9: 103.2
B10: Jan | C10: 97.7
A11: 2022 | D11: =AVERAGE(C12:C23) -> 129.38333 | E11: =MEDIAN(C12:C23) -> 126.8
B12: December | C12: 94.7
B13: Nov | C13: 111.1
B14: Oct | C14: 121.6
B15: Sept | C15: 127.5
B16: Aug | C16: 134.5
B17: July | C17: 123.7
B18: June | C18: 144.9
B19: May | C19: 140.6
B20: April | C20: 164.3
B21: March | C21: 142.6
B22: feb | C22: 126.1
B23: Jan | C23: 121
A24: 2021 | D24: =AVERAGE(C25:C36) -> 133.425 | E24: =MEDIAN(C25:C36) -> 135.35
B25: December | C25: 124.2
B26: Nov | C26: 130.8
B27: Oct | C27: 133.6
B28: Sept | C28: 135.2
B29: Aug | C29: 140
B30: July | C30: 143.9
B31: June | C31: 154.3
B32: May | C32: 145.7
B33: April | C33: 135.5
B34: March | C34: 140.6
B35: feb | C35: 102.1
B36: Jan | C36: 115.2
A37: 2020 | D37: =AVERAGE(C38:C49) -> 114.96667 | E37: =MEDIAN(C38:C49) -> 116.45
B38: December | C38: 115.1
B39: Nov | C39: 117.8
B40: Oct | C40: 131.2
...

Sheet Nominal Price to Real Price
A1: Year | B1: Nominal CPI | C1: annual inflation rate | D1: Nominal HP | E1: Real HP
A2: 1968 | B2: 28.13228 | C2: 4.27 | D2: =Macrohistory!F2 -> 24.17716 | E2: =(D2/B2)*100 -> 85.94099
A3: 1969 | B3: 29.66186 | C3: =((B3-B2)/B2)*100 -> 5.4370993 | D3: =Macrohistory!F3 -> 25.74848 | E3: =(D3/B3)*100 -> 86.806694
A4: 1970 | B4: 31.40708 | C4: =((B4-B3)/B3)*100 -> 5.8837173 | D4: =Macrohistory!F4 -> 27.8155 | E4: =(D4/B4)*100 -> 88.564426
A5: 1971 | B5: 32.73452 | C5: =((B5-B4)/B4)*100 -> 4.2265629 | D5: =Macrohistory!F5 -> 29.35155 | E5: =(D5/B5)*100 -> 89.665436
A6: 1972 | B6: 33.8059 | C6: =((B6-B5)/B5)*100 -> 3.2729363 | D6: =Macrohistory!F6 -> 30.56433 | E6: =(D6/B6)*100 -> 90.41123
A7: 1973 | B7: 35.92172 | C7: =((B7-B6)/B6)*100 -> 6.25873 | D7: =Macrohistory!F7 -> 31.19912 | E7: =(D7/B7)*100 -> 86.853079
A8: 1974 | B8: 39.87708 | C8: =((B8-B7)/B7)*100 -> 11.011054 | D8: =Macrohistory!F8 -> 33.55022 | E8: =(D8/B8)*100 -> 84.134094
A9: 1975 | B9: 43.52249 | C9: =((B9-B8)/B8)*100 -> 9.1416172 | D9: =Macrohistory!F9 -> 37.07843 | E9: =(D9/B9)*100 -> 85.193724
A10: 1976 | B10: 46.03586 | C10: =((B10-B9)/B9)*100 -> 5.7748764 | D10: =Macrohistory!F10 -> 39.81712 | E10: =(D10/B10)*100 -> 86.491531
A11: 1977 | B11: 49.01418 | C11: =((B11-B10)/B10)*100 -> 6.4695652 | D11: =Macrohistory!F11 -> 44.52566 | E11: =(D11/B11)*100 -> 90.842405
A12: 1978 | B12: 52.75392 | C12: =((B12-B11)/B11)*100 -> 7.6299144 | D12: =Macrohistory!F12 -> 50.7931 | E12: =(D12/B12)*100 -> 96.283082
A13: 1979 | B13: 57.75644 | C13: =((B13-B12)/B12)*100 -> 9.4827455 | D13: =Macrohistory!F13 -> 57.68379 | E13: =(D13/B13)*100 -> 99.874213
A14: 1980 | B14: 64.22436 | C14: =((B14-B13)/B13)*100 -> 11.198613 | D14: =Macrohistory!F14 -> 62.28163 | E14: =(D14/B14)*100 -> 96.975089
... A54: 2020 | B54: 192.6225 | C54: =((B54-B53)/B53)*100 -> 1.2483206 | D54: =Macrohistory!F54 -> 305.2215 | E54: =(D54/B54)*100 -> 158.45579

Sheet Macrohistory
A1: year | B1: avg_new_housing | C1: medprice | D1: country | E1: pop | F1: hpnom | G1: rgdpmad | H1: rgdpbarro | I1: rconsbarro | J1: gdp | K1: iy | L1: cpi | M1: ca | N1: imports | O1: exports | P1: narrowm | Q1: money | R1: stir | S1: ltrate | T1: unemp | U1: wage | V1: debtgdp | W1: revenue | X1: expenditure | Y1: xrusd | Z1: tloans | AA1: tmort | AB1: thh | AC1: tbus | AD1: bdebt | AE1: lev | AF1: ltd | AG1: noncore | AH1: crisisJST | AI1: crisisJST_old | AJ1: peg | AK1: peg_strict | AL1: peg_type | AM1: peg_base | AN1: JSTtrilemmaIV | AO1: eq_tr | AP1: housing_tr | AQ1: bond_tr | AR1: bill_rate | AS1: rent_ipolated | AT1: housing_capgain_ipolated | AU1: housing_capgain | AV1: housing_rent_rtn | AW1: housing_rent_yd | AX1: eq_capgain | AY1: eq_dp | AZ1: eq_capgain_interp | BA1: eq_tr_interp | BB1: eq_dp_interp | BC1: bond_rate | BD1: eq_div_rtn | BE1: capital_tr | BF1: risky_tr | BG1: safe_tr
A2: 1968 | B2: 125.62 | C2: ='Median Price of new US Homes'!D2 -> 24800 | D2: USA | E2: 200706 | F2: 24.17716 | G2: 14862.94 | H2: 48.40152 | I2: 42.405 | J2: 940.651 | K2: 0.193191 | L2: 28.13228 | M2: 0.59 | N2: 46.55 | O2: 47.9 | P2: 59.428 | Q2: 545.3083 | R2: 5.66 | S2: 5.64583 | T2: 24.17716 | U2: 3.6 | V2: 27.78636 | W2: 0.41 | X2: 152.973 | Y2: 178.134 | Z2: 1 | AA2: 451.003 | AB2: 249.923 | AC2: 281.904 | AD2: 169.099 | AE2: 575.917 | AF2: 5.050963 | AG2: 59.68572 | AH2: 8.474614 | AI2: 0 | AJ2: 0 | AK2: 1 | AL2: 1 | AM2: BASE | AN2: NA | AP2: 0.149738 | AQ2: 0.082211 | AR2: -0.00119 | AS2: 0.058592 | AV2: 0.028594 | AW2: 0.053617 | AX2: 0.052127 | AY2: 0.117524 | AZ2: 0.028826 | BD2: 0.056458 | BE2: 0.032214 | BF2: 0.095814 | BG2: 0.110319 | BH2: 0.0287
A3: 1969 | B3: 122.23 | C3: ='Median Price of new US Homes'!D3 -> 25600 | D3: USA | E3: 202677 | F3: 25.74848 | G3: 15179.41 | H3: 49.41949 | I3: 43.5643 | J3: 1017.615 | K3: 0.193509 | L3: 29.66186 | M3: 0.42 | N3: 50.5 | O3: 51.925 | P3: 62.029 | Q3: 578.6583 | R3: 8.22 | S3: 6.67083 | T3: 25.74848 | U3: 3.5 | V3: 29.45217 | W3: 0.372 | X3: 186.882 | Y3: 183.64 | Z3: 1 | AA3: 488.105 | AB3: 267.05 | AC3: 302.954 | AD3: 185.151 | AE3: 645.158 | AF3: 5.332874 | AG3: 64.27292 | AH3: 12.0155 | AI3: 0 | AJ3: 0 | AK3: 1 | AL3: 1 | AM3: BASE | AN3: NA | AP3: -0.11484 | AQ3: 0.119853 | AR3: -0.05536 | AS3: 0.077608 | AV3: 0.064991 | AW3: 0.054862 | AX3: 0.051514 | AY3: -0.14451 | AZ3: 0.034683 | BD3: 0.066708 | BE3: 0.029671 | BF3: 0.028863 | BG3: 0.032603 | BH3: 0.011124
A4: 1970 | B4: 119.47 | C4: ='Median Price of new US Homes'!D4 -> 23475 | D4: USA | E4: 205052 | F4: 27.8155 | G4: 15029.85 | H4: 48.9255 | I4: 44.0621 | J4: 1073.303 | K4: 0.186763 | L4: 31.40708 | M4: 2.62 | N4: 55.75 | O4: 59.725 | P4: 66.215 | Q4: 601.4 | R4: 7.18 | S4: 7.34833 | T4: 27.8155 | U4: 4.9 | V4: 30.92907 | W4: 0.363 | X4: 192.807 | Y4: 195.649 | Z4: 1 | AA4: 512.163 | AB4: 281.603 | AC4: 317.813 | AD4: 194.35 | AE4: 697.649 | AF4: 5.268326 | AG4: 60.55614 | AH4: 10.66699 | AI4: 0 | AJ4: 0 | AK4: 1 | AL4: 1 | AM4: BASE | AN4: NA | AP4: 0.02283 | AQ4: 0.13493 | AR4: 0.141949 | AS4: 0.075642 | AV4: 0.080277 | AW4: 0.054654 | AX4: 0.050592 | AY4: -0.01163 | AZ4: 0.03487 | BD4: 0.073483 | BE4: 0.034464 | BF4: 0.097142 | BG4: 0.094692 | BH4: 0.108796
A5: 1971 | B5: 171.02 | C5: ='Median Price of new US Homes'!D5 -> 25225 | D5: USA | E5: 207661 | F5: 29.35155 | G5: 15304.3 | H5: 49.94692 | I5: 45.1838 | J5: 1164.85 | K5: 0.187847 | L5: 32.73452 | M5: -0.98 | N5: 62.35 | O5: 62.975 | P5: 71.023 | Q5: 674.3917 | R5: 4.66 | S5: 6.15917 | T5: 29.35155 | U5: 5.9 | V5: 32.95552 | W5: 0.365 | X5: 187.139 | Y5: 210.172 | Z5: 1 | AA5: 568.916 | AB5: 317.894 | AC5: 357.502 | AD5: 211.414 | AE5: 770.25 | AF5: 5.103973 | AG5: 59.73378 | AH5: 10.32072 | AI5: 0 | AJ5: 0 | AK5: 1 | AL5: 1 | AM5: BASE | AN5: NA | AP5: 0.135369 | AQ5: 0.108587 | AR5: 0.179647 | AS5: 0.05005 | AV5: 0.055221 | AW5: 0.053366 | AX5: 0.050574 | AY5: 0.101277 | AZ5: 0.030957 | BD5: 0.061592 | BE5: 0.034092 | BF5: 0.117934 | BG5: 0.118563 | BH5: 0.114849
A6: 1972 | B6: 184.96 | C6: ='Median Price of new US Homes'!D6 -> 27525 | D6: USA | E6: 209896 | F6: 30.56433 | G6: 15943.87 | H6: 52.05302 | I6: 47.4633 | J6: 1279.11 | K6: 0.194765 | L6: 33.8059 | M6: -5.26 | N6: 74.225 | O6: 70.85 | P6: 77.044 | Q6: 758.1333 | R6: 4.43 | S6: 6.21 | T6: 30.56433 | U6: 5.6 | V6: 35.27391 | W6: 0.357 | X6: 207.309 | Y6: 230.681 | Z6: 1 | AA6: 662.369 | AB6: 372.822 | AC6: 416.553 | AD6: 245.816 | AE6: 870.747 | AF6: 4.769589 | AG6: 61.96682 | AH6: 11.36904 | AI6: 0 | AJ6: 0 | AK6: 0 | AL6: 0 | AM6: BASE | AN6: NA | AP6: 0.216598 | AQ6: 0.094272 | AR6: 0.055526 | AS6: 0.046658 | AV6: 0.04132 | AW6: 0.052952 | AX6: 0.050851 | AY6: 0.184834 | AZ6: 0.026809 | BD6: 0.0621 | BE6: 0.031764 | BF6: 0.12625 | BG6: 0.140474 | BH6: 0.051092
A7: 1973 | B7: 170.43 | C7: ='Median Price of new US Homes'!D7 -> 32600 | D7: USA | E7: 211909 | F7: 31.19912 | G7: 16689.34 | H7: 54.55263 | I7: 49.3361 | J7: 1425.376 | K7: 0.199274 | L7: 35.92172 | M7: 7.58 | N7: 91.175 | O7: 95.275 | P7: 83.477 | Q7: 831.8 | R7: 8.73 | S7: 6.8425 | T7: 31.19912 | U7: 4.9 | V7: 37.76404 | W7: 0.344 | X7: 230.799 | Y7: 245.707 | Z7: 1 | AA7: 778.909 | AB7: 429.252 | AC7: 479.377 | AD7: 299.532 | AE7: 1025.645 | AF7: 4.674504 | AG7: 66.3463 | AH7: 13.32381 | AI7: 0 | AJ7: 0 | AK7: 0 | AL7: 0 | AM7: BASE | AN7: NA | AP7: -0.1646 | AQ7: 0.074986 | AR7: -0.03833 | AS7: 0.084158 | AV7: 0.020769 | AW7: 0.054217 | AX7: 0.053114 | AY7: -0.19336 | AZ7: 0.035662 | BD7: 0.068425 | BE7: 0.028766 | BF7: 0.005792 | BG7: 0.002384 | BH7: 0.022912
A8: 1974 | B8: 111.48 | C8: ='Median Price of new US Homes'!D8 -> 36050 | D8: USA | E8: 213854 | F8: 33.55022 | G8: 16491.27 | H8: 53.77678 | I8: 48.509 | J8: 1545.243 | K8: 0.194505 | L8: 39.87708 | M8: 1.7 | N8: 127.475 | O8: 126.65 | P8: 91.442 | Q8: 880.6667 | R8: 10.5 | S8: 7.55667 | T8: 33.55022 | U8: 5.6 | V8: 40.80371 | W8: 0.326 | X8: 263.224 | Y8: 269.359 | Z8: 1 | AA8: 855.572 | AB8: 464.366 | AC8: 512.273 | AD8: 343.299 | AE8: 1072.85 | AF8: 3.859146 | AG8: 66.04999 | AH8: 12.63027 | AI8: 0 | AJ8: 0 | AK8: 0 | AL8: 0 | AM8: BASE | AN8: NA | AP8: -0.25438 | AQ8: 0.132476 | AR8: 0.025545 | AS8: 0.102442 | AV8: 0.075358 | AW8: 0.057118 | AX8: 0.053115 | AY8: -0.29236 | AZ8: 0.053675 | BD8: 0.075567 | BE8: 0.037983 | BF8: 0.048292 | BG8: 0.044881 | BH8: 0.063994
A9: 1975 | B9: 97.15 | C9: ='Median Price of new US Homes'!D9 -> 39275 | D9: USA | E9: 215973 | F9: 37.07843 | G9: 16283.63 | H9: 53.14003 | I9: 49.1432 | J9: 1684.904 | K9: 0.182942 | L9: 43.52249 | M9: 17.88 | N9: 122.725 | O9: 138.7 | P9: 96.743 | Q9: 963.6667 | R9: 5.82 | S9: 7.9875 | T9: 37.07843 | U9: 8.5 | V9: 44.599 | W9: 0.336 | X9: 279.09 | Y9: 332.332 | Z9: 1 | AA9: 887.505 | AB9: 503.668 | AC9: 550.832 | AD9: 336.673 | AE9: 1419.617 | AF9: 4.025463 | AG9: 63.46128 | AH9: 12.18432 | AI9: 0 | AJ9: 0 | AK9: 0 | AL9: 0 | AM9: BASE | AN9: NA | AP9: 0.377367 | AQ9: 0.162001 | AR9: 0.065095 | AS9: 0.064367 | AV9: 0.105162 | AW9: 0.056839 | AX9: 0.05143 | AY9: 0.322499 | AZ9: 0.041488 | BD9: 0.079875 | BE9: 0.054868 | BF9: 0.191532 | BG9: 0.21822 | BH9: 0.064731
A10: 1976 | B10: 128.11 | C10: ='Median Price of new US Homes'!D10 -> 44225 | D10: USA | E10: 218035 | F10: 39.81712 | G10: 16975.09 | H10: 55.46424 | I10: 51.3828 | J10: 1873.412 | K10: 0.186988 | L10: 46.03586 | M10: 3.84 | N10: 151.125 | O10: 149.525 | P10: 102.95 | Q10: 1086.592 | R10: 5.04 | S10: 7.61083 | T10: 39.81712 | U10: 7.7 | V10: 48.18822 | W10: 0.351 | X10: 298.06 | Y10: 371.792 | Z10: 1 | AA10: 977.203 | AB10: 570.902 | AC10: 626.699 | AD10: 350.504 | AE10: 1536.367 | AF10: 4.261487 | AG10: 63.17842 | AH10: 12.37701 | AI10: 0 | AJ10: 0 | AK10: 0 | AL10: 0 | AM10: BASE | AN10: NA | AP10: 0.226043 | AQ10: 0.129157 | AR10: 0.173386 | AS10: 0.052683 | AV10: 0.073862 | AW10: 0.055295 | AX10: 0.051492 | AY10: 0.180383 | AZ10: 0.038682 | BD10: 0.076108 | BE10: 0.04566 | BF10: 0.149056 | BG10: 0.156697 | BH10: 0.113034
A11: 1977 | B11: 165.59 | C11: ='Median Price of new US Homes'!D11 -> 48900 | D11: USA | E11: 220239 | F11: 44.52566 | G11: 17566.5 | H11: 57.46356 | I11: 53.0412 | J11: 2081.826 | K11: 0.200247 | L11: 49.01418 | M11: -15.1 | N11: 182.425 | O11: 159.35 | P11: 112.061 | Q11: 1221.383 | R11: 5.54 | S11: 7.41917 | T11: 44.52566 | U11: 7.1 | V11: 52.44719 | W11: 0.348 | X11: 355.559 | Y11: 409.218 | Z11: 1 | AA11: 1125.51 | AB11: 665.606 | AC11: 738.562 | AD11: 386.948 | AE11: 1723.78 | AF11: 4.067384 | AG11: 64.73243 | AH11: 13.09679 | AI11: 0 | AJ11: 0 | AK11: 0 | AL11: 0 | AM11: BASE | AN11: NA | AP11: -0.05931 | AQ11: 0.174269 | AR11: 0.014055 | AS11: 0.056408 | AV11: 0.118256 | AW11: 0.056013 | AX11: 0.05009 | AY11: -0.10392 | AZ11: 0.049776 | BD11: 0.074192 | BE11: 0.044604 | BF11: 0.10335 | BG11: 0.117704 | BH11: 0.035232
A12: 1978 | B12: 168.36 | C12: ='Median Price of new US Homes'!D12 -> 55850 | D12: USA | E12: 222585 | F12: 50.7931 | G12: 18372.97 | H12: 60.05052 | I12: 54.8057 | J12: 2351.599 | K12: 0.213308 | L12: 52.75392 | M12: -15.747 | N12: 212.25 | O12: 186.875 | P12: 121.816 | Q12: 1322.408 | R12: 7.93 | S12: 8.41 | T12: 50.7931 | U12: 6.1 | V12: 56.96376 | W12: 0.341 | X12: 399.561 | Y12: 458.746 | Z12: 1 | AA12: 1296.421 | AB12: 763.103 | AC12: 857.329 | AD12: 439.092 | AE12: 1975.814 | AF12: 3.948125 | AG12: 67.53503 | AH12: 14.84381 | AI12: 0 | AJ12: 0 | AK12: 0 | AL12: 0 | AM12: BASE | AN12: NA | AP12: 0.078448 | AQ12: 0.195388 | AR12: -0.02965 | AS12: 0.082217 | AV12: 0.140759 | AW12: 0.054629 | AX12: 0.047888 | AY12: 0.024408 | AZ12: 0.052752 | BD12: 0.0841 | BE12: 0.05404 | BF12: 0.145024 | BG12: 0.169516 | BH12: 0.026283
A13: 1979 | B13: 145.41 | C13: ='Median Price of new US Homes'!D13 -> 62750 | D13: USA | E13: 225055 | F13: 57.68379 | G13: 18789.39 | H13: 61.28141 | I13: 55.5304 | J13: 2627.334 | K13: 0.219889 | L13: 57.75644 | M13: -0.1567 | N13: 252.675 | O13: 230.15 | P13: 131.347 | Q13: 1425.767 | R13: 11.19 | S13: 9.4425 | T13: 57.68379 | U13: 5.8 | V13: 61.85815 | W13: 0.323 | X13: 463.302 | Y13: 504.028 | Z13: 1 | AA13: 1446.002 | AB13: 845.813 | AC13: 955.312 | AD13: 490.69 | AE13: 2310.241 | AF13: 3.897225 | AG13: 68.64673 | AH13: 16.17924 | AI13: 0 | AJ13: 0 | AK13: 0 | AL13: 0 | AM13: BASE | AN13: NA | AP13: 0.180418 | AQ13: 0.188324 | AR13: -0.0159 | AS13: 0.11225 | AV13: 0.135662 | AW13: 0.052662 | AX13: 0.046371 | AY13: 0.121631 | AZ13: 0.052412 | BD13: 0.094425 | BE13: 0.058787 | BF13: 0.164819 | BG13: 0.186599 | BH13: 0.048177
... A54: 2020 | B54: 114.97 | C54: ='Median Price of new US Homes'!D54 -> 336950 | D54: USA | E54: 329239.7 | F54: 305.2215 | G54: 33646.26 | H54: 110.823 | I54: 109.7932 | J54: 20893.7 | K54: 0.214368 | L54: 192.6225 | M54: -616.087 | N54: 2774.597 | O54: 2123.411 | P54: 5206.5 | Q54: 17677.43 | R54: 0.37 | S54: 0.894167 | T54: 305.2215 | U54: 8.05 | V54: 259.1803 | W54: 1.281 | X54: 3421.162 | Y54: 6550.396 | Z54: 1 | AA54: 14528.9 | AB54: 8896.753 | AC54: 8682.248 | AD54: 5846.647 | AE54: 30068.02 | AF54: 8.533194 | AG54: 59.40991 | AH54: 10.97222 | AI54: 0 | AJ54: 0 | AK54: 0 | AL54: 0 | AM54: BASE | AN54: NA | AP54: 0.125354 | AQ54: 0.124171 | AR54: 0.118656 | AS54: 0.0038 | AV54: 0.078573 | AW54: 0.045598 | AX54: 0.042277 | AY54: 0.105064 | AZ54: 0.018361 | BD54: 0.008942 | BE54: 0.02029 | BF54: 0.106476 | BG54: 0.124902 | BH54: 0.061228

Sheet Median Price of new US Homes
A1: observation_date | B1: MSPUS | C1: year | D1: yearly avg
A2: 24838 | B2: 23900 | C2: 1968 | D2: =AVERAGE(B2:B5) -> 24800
A3: 24929 | B3: 24900 | C3: 1969 | D3: =AVERAGE(B6:B9) -> 25600
A4: 25020 | B4: 24800 | C4: 1970 | D4: =AVERAGE(B10:B13) -> 23475
A5: 25112 | B5: 25600 | C5: 1971 | D5: =AVERAGE(B14:B17) -> 25225
A6: 25204 | B6: 25700 | C6: 1972 | D6: =AVERAGE(B18:B21) -> 27525
A7: 25294 | B7: 25900 | C7: 1973 | D7: =AVERAGE(B22:B25) -> 32600
A8: 25385 | B8: 25900 | C8: 1974 | D8: =AVERAGE(B26:B29) -> 36050
A9: 25477 | B9: 24900 | C9: 1975 | D9: =AVERAGE(B30:B33) -> 39275
A10: 25569 | B10: 23900 | C10: 1976 | D10: =AVERAGE(B34:B37) -> 44225
A11: 25659 | B11: 24400 | C11: 1977 | D11: =AVERAGE(B38:B41) -> 48900
A12: 25750 | B12: 23000 | C12: 1978 | D12: =AVERAGE(B42:B45) -> 55850
A13: 25842 | B13: 22600 | C13: 1979 | D13: =AVERAGE(B46:B49) -> 62750
A14: 25934 | B14: 24300 | C14: 1980 | D14: =AVERAGE(B50:B53) -> 64750
A15: 26024 | B15: 25800 | C15: 1981 | D15: =AVERAGE(B54:B57) -> 68950
A16: 26115 | B16: 25300 | C16: 1982 | D16: =AVERAGE(B58:B61) -> 69225
A17: 26207 | B17: 25500 | C17: 1983 | D17: =AVERAGE(B62:B65) -> 75375
A18: 26299 | B18: 26200 | C18: 1984 | D18: =AVERAGE(B66:B69) -> 79950
A19: 26390 | B19: 26800 | C19: 1985 | D19: =AVERAGE(B70:B73) -> 84275
A20: 26481 | B20: 27900 | C20: 1986 | D20: =AVERAGE(B74:B77) -> 92025
A21: 26573 | B21: 29200 | C21: 1987 | D21: =AVERAGE(B78:B81) -> 104700
A22: 26665 | B22: 30200 | C22: 1988 | D22: =AVERAGE(B82:B85) -> 112225
A23: 26755 | B23: 32700 | C23: 1989 | D23: =AVERAGE(B86:B89) -> 120425
A24: 26846 | B24: 33500 | C24: 1990 | D24: =AVERAGE(B90:B93) -> 122300
A25: 26938 | B25: 34000 | C25: 1991 | D25: =AVERAGE(B94:B97) -> 119975
A26: 27030 | B26: 35200 | C26: 1992 | D26: =AVERAGE(B98:B101) -> 121375
A27: 27120 | B27: 35600 | C27: 1993 | D27: =AVERAGE(B102:B105) -> 126500
A28: 27211 | B28: 36200 | C28: 1994 | D28: =AVERAGE(B106:B109) -> 130425
A29: 27303 | B29: 37200 | C29: 1995 | D29: =AVERAGE(B110:B113) -> 133475
A30: 27395 | B30: 38100 | C30: 1996 | D30: =AVERAGE(B114:B117) -> 140250
A31: 27485 | B31: 39000 | C31: 1997 | D31: =AVERAGE(B118:B121) -> 145000
A32: 27576 | B32: 38800 | C32: 1998 | D32: =AVERAGE(B122:B125) -> 151925
A33: 27668 | B33: 41200 | C33: 1999 | D33: =AVERAGE(B126:B129) -> 160125
A34: 27760 | B34: 42800 | C34: 2000 | D34: =AVERAGE(B130:B133) -> 167550
A35: 27851 | B35: 44200 | C35: 2001 | D35: =AVERAGE(B134:B137) -> 173100
A36: 27942 | B36: 44400 | C36: 2002 | D36: =AVERAGE(B138:B141) -> 186025
A37: 28034 | B37: 45500 | C37: 2003 | D37: =AVERAGE(B142:B145) -> 192125
A38: 28126 | B38: 46300 | C38: 2004 | D38: =AVERAGE(B146:B149) -> 218150
A39: 28216 | B39: 48900 | C39: 2005 | D39: =AVERAGE(B150:B153) -> 236550
A40: 28307 | B40: 48800 | C40: 2006 | D40: =AVERAGE(B154:B157) -> 243750
...
